2025-08-11 15:55:15 ERROR (MainThread) [aiohttp.server] Error handling request
Traceback (most recent call last):
  File "/usr/local/lib/python3.9/site-packages/aiohttp/web_protocol.py", line 334, in data_received
    messages, upgraded, tail = self._request_parser.feed_data(data)
  File "aiohttp/_http_parser.pyx", line 551, in aiohttp._http_parser.HttpParser.feed_data
aiohttp.http_exceptions.BadStatusLine: 400, message="Bad status line 'Invalid method encountered'"
2025-08-11 15:55:15 ERROR (MainThread) [aiohttp.server] Error handling request
Traceback (most recent call last):
  File "/usr/local/lib/python3.9/site-packages/aiohttp/web_protocol.py", line 334, in data_received
    messages, upgraded, tail = self._request_parser.feed_data(data)
  File "aiohttp/_http_parser.pyx", line 551, in aiohttp._http_parser.HttpParser.feed_data
aiohttp.http_exceptions.BadStatusLine: 400, message="Bad status line 'Invalid method encountered'"
2025-08-11 15:55:15 ERROR (MainThread) [aiohttp.server] Error handling request
Traceback (most recent call last):
  File "/usr/local/lib/python3.9/site-packages/aiohttp/web_protocol.py", line 334, in data_received
    messages, upgraded, tail = self._request_parser.feed_data(data)
  File "aiohttp/_http_parser.pyx", line 551, in aiohttp._http_parser.HttpParser.feed_data
aiohttp.http_exceptions.BadStatusLine: 400, message="Bad status line 'Invalid method encountered'"
2025-08-11 15:55:15 ERROR (MainThread) [aiohttp.server] Error handling request
Traceback (most recent call last):
  File "/usr/local/lib/python3.9/site-packages/aiohttp/web_protocol.py", line 334, in data_received
    messages, upgraded, tail = self._request_parser.feed_data(data)
  File "aiohttp/_http_parser.pyx", line 551, in aiohttp._http_parser.HttpParser.feed_data
aiohttp.http_exceptions.BadStatusLine: 400, message="Bad status line 'Invalid method encountered'"
2025-08-11 15:55:22 ERROR (MainThread) [aiohttp.server] Error handling request
Traceback (most recent call last):
  File "/usr/local/lib/python3.9/site-packages/aiohttp/web_protocol.py", line 334, in data_received
    messages, upgraded, tail = self._request_parser.feed_data(data)
  File "aiohttp/_http_parser.pyx", line 551, in aiohttp._http_parser.HttpParser.feed_data
aiohttp.http_exceptions.BadStatusLine: 400, message="Bad status line 'Invalid method encountered'"
2025-08-11 15:55:22 ERROR (MainThread) [aiohttp.server] Error handling request
Traceback (most recent call last):
  File "/usr/local/lib/python3.9/site-packages/aiohttp/web_protocol.py", line 334, in data_received
    messages, upgraded, tail = self._request_parser.feed_data(data)
  File "aiohttp/_http_parser.pyx", line 551, in aiohttp._http_parser.HttpParser.feed_data
aiohttp.http_exceptions.BadStatusLine: 400, message="Bad status line 'Invalid method encountered'"
2025-08-11 15:55:22 ERROR (MainThread) [aiohttp.server] Error handling request
Traceback (most recent call last):
  File "/usr/local/lib/python3.9/site-packages/aiohttp/web_protocol.py", line 334, in data_received
    messages, upgraded, tail = self._request_parser.feed_data(data)
  File "aiohttp/_http_parser.pyx", line 551, in aiohttp._http_parser.HttpParser.feed_data
aiohttp.http_exceptions.BadStatusLine: 400, message="Bad status line 'Invalid method encountered'"
2025-08-11 15:55:22 ERROR (MainThread) [aiohttp.server] Error handling request
Traceback (most recent call last):
  File "/usr/local/lib/python3.9/site-packages/aiohttp/web_protocol.py", line 334, in data_received
    messages, upgraded, tail = self._request_parser.feed_data(data)
  File "aiohttp/_http_parser.pyx", line 551, in aiohttp._http_parser.HttpParser.feed_data
aiohttp.http_exceptions.BadStatusLine: 400, message="Bad status line 'Invalid method encountered'"
2025-08-11 15:55:26 ERROR (MainThread) [aiohttp.server] Error handling request
Traceback (most recent call last):
  File "/usr/local/lib/python3.9/site-packages/aiohttp/web_protocol.py", line 334, in data_received
    messages, upgraded, tail = self._request_parser.feed_data(data)
  File "aiohttp/_http_parser.pyx", line 551, in aiohttp._http_parser.HttpParser.feed_data
aiohttp.http_exceptions.BadStatusLine: 400, message="Bad status line 'Invalid method encountered'"
2025-08-11 15:55:26 ERROR (MainThread) [aiohttp.server] Error handling request
Traceback (most recent call last):
  File "/usr/local/lib/python3.9/site-packages/aiohttp/web_protocol.py", line 334, in data_received
    messages, upgraded, tail = self._request_parser.feed_data(data)
  File "aiohttp/_http_parser.pyx", line 551, in aiohttp._http_parser.HttpParser.feed_data
aiohttp.http_exceptions.BadStatusLine: 400, message="Bad status line 'Invalid method encountered'"
2025-08-11 15:55:26 ERROR (MainThread) [aiohttp.server] Error handling request
Traceback (most recent call last):
  File "/usr/local/lib/python3.9/site-packages/aiohttp/web_protocol.py", line 334, in data_received
    messages, upgraded, tail = self._request_parser.feed_data(data)
  File "aiohttp/_http_parser.pyx", line 551, in aiohttp._http_parser.HttpParser.feed_data
aiohttp.http_exceptions.BadStatusLine: 400, message="Bad status line 'Invalid method encountered'"
2025-08-11 15:55:26 ERROR (MainThread) [aiohttp.server] Error handling request
Traceback (most recent call last):
  File "/usr/local/lib/python3.9/site-packages/aiohttp/web_protocol.py", line 334, in data_received
    messages, upgraded, tail = self._request_parser.feed_data(data)
  File "aiohttp/_http_parser.pyx", line 551, in aiohttp._http_parser.HttpParser.feed_data
aiohttp.http_exceptions.BadStatusLine: 400, message="Bad status line 'Invalid method encountered'"
2025-08-11 15:55:29 ERROR (MainThread) [aiohttp.server] Error handling request
Traceback (most recent call last):
  File "/usr/local/lib/python3.9/site-packages/aiohttp/web_protocol.py", line 334, in data_received
    messages, upgraded, tail = self._request_parser.feed_data(data)
  File "aiohttp/_http_parser.pyx", line 551, in aiohttp._http_parser.HttpParser.feed_data
aiohttp.http_exceptions.BadStatusLine: 400, message="Bad status line 'Invalid method encountered'"
2025-08-11 15:55:29 ERROR (MainThread) [aiohttp.server] Error handling request
Traceback (most recent call last):
  File "/usr/local/lib/python3.9/site-packages/aiohttp/web_protocol.py", line 334, in data_received
    messages, upgraded, tail = self._request_parser.feed_data(data)
  File "aiohttp/_http_parser.pyx", line 551, in aiohttp._http_parser.HttpParser.feed_data
aiohttp.http_exceptions.BadStatusLine: 400, message="Bad status line 'Invalid method encountered'"
2025-08-11 15:55:29 ERROR (MainThread) [aiohttp.server] Error handling request
Traceback (most recent call last):
  File "/usr/local/lib/python3.9/site-packages/aiohttp/web_protocol.py", line 334, in data_received
    messages, upgraded, tail = self._request_parser.feed_data(data)
  File "aiohttp/_http_parser.pyx", line 551, in aiohttp._http_parser.HttpParser.feed_data
aiohttp.http_exceptions.BadStatusLine: 400, message="Bad status line 'Invalid method encountered'"
2025-08-11 15:55:29 ERROR (MainThread) [aiohttp.server] Error handling request
Traceback (most recent call last):
  File "/usr/local/lib/python3.9/site-packages/aiohttp/web_protocol.py", line 334, in data_received
    messages, upgraded, tail = self._request_parser.feed_data(data)
  File "aiohttp/_http_parser.pyx", line 551, in aiohttp._http_parser.HttpParser.feed_data
aiohttp.http_exceptions.BadStatusLine: 400, message="Bad status line 'Invalid method encountered'"
2025-08-11 15:56:56 ERROR (MainThread) [homeassistant.components.websocket_api.http.connection] [139962417338352] Error handling message: invalid ISO 4217 formatted currency for dictionary value @ data['currency']. Got 'rmb'
2025-08-11 16:03:45 ERROR (MainThread) [homeassistant.components.websocket_api.http.connection] [139962415626704] Error handling message: Unknown error
Traceback (most recent call last):
  File "/usr/src/homeassistant/homeassistant/components/websocket_api/decorators.py", line 27, in _handle_async_response
    await func(hass, connection, msg)
  File "/usr/src/homeassistant/homeassistant/components/frontend/__init__.py", line 692, in websocket_get_translations
    resources = await async_get_translations(
  File "/usr/src/homeassistant/homeassistant/helpers/translation.py", line 313, in async_get_translations
    cached = await cache.async_fetch(language, category, components)
  File "/usr/src/homeassistant/homeassistant/helpers/translation.py", line 223, in async_fetch
    await self._async_load(language, components_to_load)
  File "/usr/src/homeassistant/homeassistant/helpers/translation.py", line 238, in _async_load
    for translation_strings in await asyncio.gather(
  File "/usr/src/homeassistant/homeassistant/helpers/translation.py", line 158, in async_get_component_strings
    await gather_with_concurrency(
  File "/usr/src/homeassistant/homeassistant/util/async_.py", line 170, in gather_with_concurrency
    return await gather(
  File "/usr/src/homeassistant/homeassistant/util/async_.py", line 168, in sem_task
    return await task
  File "/usr/src/homeassistant/homeassistant/loader.py", line 566, in async_get_integration
    integration = await _async_get_integration(hass, domain)
  File "/usr/src/homeassistant/homeassistant/loader.py", line 594, in _async_get_integration
    raise IntegrationNotFound(domain)
homeassistant.loader.IntegrationNotFound: Integration 'mcp_server' not found.
2025-08-11 16:03:45 ERROR (MainThread) [homeassistant.config_entries] Cannot find integration mcp_server
2025-08-11 16:03:45 ERROR (MainThread) [homeassistant.components.websocket_api.http.connection] [139962415626704] Error handling message: Unknown error
Traceback (most recent call last):
  File "/usr/src/homeassistant/homeassistant/components/websocket_api/decorators.py", line 27, in _handle_async_response
    await func(hass, connection, msg)
  File "/usr/src/homeassistant/homeassistant/components/frontend/__init__.py", line 692, in websocket_get_translations
    resources = await async_get_translations(
  File "/usr/src/homeassistant/homeassistant/helpers/translation.py", line 313, in async_get_translations
    cached = await cache.async_fetch(language, category, components)
  File "/usr/src/homeassistant/homeassistant/helpers/translation.py", line 223, in async_fetch
    await self._async_load(language, components_to_load)
  File "/usr/src/homeassistant/homeassistant/helpers/translation.py", line 238, in _async_load
    for translation_strings in await asyncio.gather(
  File "/usr/src/homeassistant/homeassistant/helpers/translation.py", line 158, in async_get_component_strings
    await gather_with_concurrency(
  File "/usr/src/homeassistant/homeassistant/util/async_.py", line 170, in gather_with_concurrency
    return await gather(
  File "/usr/src/homeassistant/homeassistant/util/async_.py", line 168, in sem_task
    return await task
  File "/usr/src/homeassistant/homeassistant/loader.py", line 566, in async_get_integration
    integration = await _async_get_integration(hass, domain)
  File "/usr/src/homeassistant/homeassistant/loader.py", line 594, in _async_get_integration
    raise IntegrationNotFound(domain)
homeassistant.loader.IntegrationNotFound: Integration 'mcp_server' not found.
2025-08-11 16:04:09 ERROR (MainThread) [homeassistant.components.websocket_api.http.connection] [139962414913760] Error handling message: Unknown error
Traceback (most recent call last):
  File "/usr/src/homeassistant/homeassistant/components/websocket_api/decorators.py", line 27, in _handle_async_response
    await func(hass, connection, msg)
  File "/usr/src/homeassistant/homeassistant/components/frontend/__init__.py", line 692, in websocket_get_translations
    resources = await async_get_translations(
  File "/usr/src/homeassistant/homeassistant/helpers/translation.py", line 313, in async_get_translations
    cached = await cache.async_fetch(language, category, components)
  File "/usr/src/homeassistant/homeassistant/helpers/translation.py", line 223, in async_fetch
    await self._async_load(language, components_to_load)
  File "/usr/src/homeassistant/homeassistant/helpers/translation.py", line 238, in _async_load
    for translation_strings in await asyncio.gather(
  File "/usr/src/homeassistant/homeassistant/helpers/translation.py", line 158, in async_get_component_strings
    await gather_with_concurrency(
  File "/usr/src/homeassistant/homeassistant/util/async_.py", line 170, in gather_with_concurrency
    return await gather(
  File "/usr/src/homeassistant/homeassistant/util/async_.py", line 168, in sem_task
    return await task
  File "/usr/src/homeassistant/homeassistant/loader.py", line 566, in async_get_integration
    integration = await _async_get_integration(hass, domain)
  File "/usr/src/homeassistant/homeassistant/loader.py", line 594, in _async_get_integration
    raise IntegrationNotFound(domain)
homeassistant.loader.IntegrationNotFound: Integration 'mcp_server' not found.
2025-08-11 16:04:09 ERROR (MainThread) [homeassistant.config_entries] Cannot find integration mcp_server
2025-08-11 16:04:09 ERROR (MainThread) [homeassistant.components.websocket_api.http.connection] [139962414913760] Error handling message: Unknown error
Traceback (most recent call last):
  File "/usr/src/homeassistant/homeassistant/components/websocket_api/decorators.py", line 27, in _handle_async_response
    await func(hass, connection, msg)
  File "/usr/src/homeassistant/homeassistant/components/frontend/__init__.py", line 692, in websocket_get_translations
    resources = await async_get_translations(
  File "/usr/src/homeassistant/homeassistant/helpers/translation.py", line 313, in async_get_translations
    cached = await cache.async_fetch(language, category, components)
  File "/usr/src/homeassistant/homeassistant/helpers/translation.py", line 223, in async_fetch
    await self._async_load(language, components_to_load)
  File "/usr/src/homeassistant/homeassistant/helpers/translation.py", line 238, in _async_load
    for translation_strings in await asyncio.gather(
  File "/usr/src/homeassistant/homeassistant/helpers/translation.py", line 158, in async_get_component_strings
    await gather_with_concurrency(
  File "/usr/src/homeassistant/homeassistant/util/async_.py", line 170, in gather_with_concurrency
    return await gather(
  File "/usr/src/homeassistant/homeassistant/util/async_.py", line 168, in sem_task
    return await task
  File "/usr/src/homeassistant/homeassistant/loader.py", line 566, in async_get_integration
    integration = await _async_get_integration(hass, domain)
  File "/usr/src/homeassistant/homeassistant/loader.py", line 594, in _async_get_integration
    raise IntegrationNotFound(domain)
homeassistant.loader.IntegrationNotFound: Integration 'mcp_server' not found.
2025-08-11 16:05:17 ERROR (MainThread) [homeassistant.config_entries] Cannot find integration mcp_server
2025-08-11 16:05:17 ERROR (MainThread) [homeassistant.components.websocket_api.http.connection] [139962414725872] Error handling message: Unknown error
Traceback (most recent call last):
  File "/usr/src/homeassistant/homeassistant/components/websocket_api/decorators.py", line 27, in _handle_async_response
    await func(hass, connection, msg)
  File "/usr/src/homeassistant/homeassistant/components/frontend/__init__.py", line 692, in websocket_get_translations
    resources = await async_get_translations(
  File "/usr/src/homeassistant/homeassistant/helpers/translation.py", line 313, in async_get_translations
    cached = await cache.async_fetch(language, category, components)
  File "/usr/src/homeassistant/homeassistant/helpers/translation.py", line 223, in async_fetch
    await self._async_load(language, components_to_load)
  File "/usr/src/homeassistant/homeassistant/helpers/translation.py", line 238, in _async_load
    for translation_strings in await asyncio.gather(
  File "/usr/src/homeassistant/homeassistant/helpers/translation.py", line 158, in async_get_component_strings
    await gather_with_concurrency(
  File "/usr/src/homeassistant/homeassistant/util/async_.py", line 170, in gather_with_concurrency
    return await gather(
  File "/usr/src/homeassistant/homeassistant/util/async_.py", line 168, in sem_task
    return await task
  File "/usr/src/homeassistant/homeassistant/loader.py", line 566, in async_get_integration
    integration = await _async_get_integration(hass, domain)
  File "/usr/src/homeassistant/homeassistant/loader.py", line 594, in _async_get_integration
    raise IntegrationNotFound(domain)
homeassistant.loader.IntegrationNotFound: Integration 'mcp_server' not found.
2025-08-11 16:05:17 ERROR (MainThread) [homeassistant.components.websocket_api.http.connection] [139962414725872] Error handling message: Unknown error
Traceback (most recent call last):
  File "/usr/src/homeassistant/homeassistant/components/websocket_api/decorators.py", line 27, in _handle_async_response
    await func(hass, connection, msg)
  File "/usr/src/homeassistant/homeassistant/components/frontend/__init__.py", line 692, in websocket_get_translations
    resources = await async_get_translations(
  File "/usr/src/homeassistant/homeassistant/helpers/translation.py", line 313, in async_get_translations
    cached = await cache.async_fetch(language, category, components)
  File "/usr/src/homeassistant/homeassistant/helpers/translation.py", line 223, in async_fetch
    await self._async_load(language, components_to_load)
  File "/usr/src/homeassistant/homeassistant/helpers/translation.py", line 238, in _async_load
    for translation_strings in await asyncio.gather(
  File "/usr/src/homeassistant/homeassistant/helpers/translation.py", line 158, in async_get_component_strings
    await gather_with_concurrency(
  File "/usr/src/homeassistant/homeassistant/util/async_.py", line 170, in gather_with_concurrency
    return await gather(
  File "/usr/src/homeassistant/homeassistant/util/async_.py", line 168, in sem_task
    return await task
  File "/usr/src/homeassistant/homeassistant/loader.py", line 566, in async_get_integration
    integration = await _async_get_integration(hass, domain)
  File "/usr/src/homeassistant/homeassistant/loader.py", line 594, in _async_get_integration
    raise IntegrationNotFound(domain)
homeassistant.loader.IntegrationNotFound: Integration 'mcp_server' not found.
